Workbook
Name вахта: #REF!
Name вахтовый: #REF!
Name ддд: [1]Лист1!$A$1:$IV$65536
Name ло: [2]Лист1!$1:$1048576
Name ппп: #REF!
Name реж: '[3]впр режим'!$1:$1048576
Name ррр: #REF!
Name т: [4]режим!$1:$1048576
Name ш: #REF!

Sheet 93
G1: Кезекшілік журналы/тәуліктік ақпарат
F2: ТҚ-93 мәліметі | I2: " " | M2: 2026ж. | P2: Шебер:
A4: №№ | B4: № ГУ | C4: № ЗУ | D4: Отвод | E4: № скв | F4: гор | G4: Режим | J4: Рбуф | K4: Рзат | L4: Ескерту | M4: Мәлімет
G5: Qж | H5: % | I5: Qн
A6: 1 | B6: ГУ-93 | C6: ГУ-93 ЗУ - 93а | D6: 1 | E6: 4218 | F6: =VLOOKUP(E6,ддд,2,FALSE) -> 13 | G6: =VLOOKUP(E6,ддд,3,FALSE) -> 20 | H6: =VLOOKUP(E6,ддд,4,FALSE) -> 75 | I6: =VLOOKUP(E6,ддд,5,FALSE) -> 4.195 | M6: Барлығы- | O6: Жұмыста- | Q6: Тұрғаны-
A7: 2 | D7: 2 | E7: 7108 | F7: =VLOOKUP(E7,ддд,2,FALSE) -> 16 | G7: =VLOOKUP(E7,ддд,3,FALSE) -> 75 | H7: =VLOOKUP(E7,ддд,4,FALSE) -> 92 | I7: =VLOOKUP(E7,ддд,5,FALSE) -> 5.034 | M7: Бас құбыр- | O7: Қазан- | Q7: ГӨЗ-
A8: 3 | D8: 3 | E8: 9797 | F8: =VLOOKUP(E8,ддд,2,FALSE) -> 15 | G8: =VLOOKUP(E8,ддд,3,FALSE) -> 40 | H8: =VLOOKUP(E8,ддд,4,FALSE) -> 85 | I8: =VLOOKUP(E8,ддд,5,FALSE) -> 5.034 | M8: Химреагент
A9: 4 | D9: 5 | E9: 4774 | F9: =VLOOKUP(E9,ддд,2,FALSE) -> 15 | G9: =VLOOKUP(E9,ддд,3,FALSE) -> 35 | H9: =VLOOKUP(E9,ддд,4,FALSE) -> 85 | I9: =VLOOKUP(E9,ддд,5,FALSE) -> 4.40475 | M9: объект | N9: деңгейі | P9: объект | Q9: деңгейі
A10: 5 | D10: 6 | E10: 8361 | F10: =VLOOKUP(E10,ддд,2,FALSE) -> 16 | G10: =VLOOKUP(E10,ддд,3,FALSE) -> 125 | H10: =VLOOKUP(E10,ддд,4,FALSE) -> 94 | I10: =VLOOKUP(E10,ддд,5,FALSE) -> 6.2925
A11: 6 | D11: 7 | E11: 9731 | F11: =VLOOKUP(E11,ддд,2,FALSE) -> 15 | G11: =VLOOKUP(E11,ддд,3,FALSE) -> 45 | H11: =VLOOKUP(E11,ддд,4,FALSE) -> 90 | I11: =VLOOKUP(E11,ддд,5,FALSE) -> 3.7755
A12: 7 | D12: 8 | E12: 7958 | F12: =VLOOKUP(E12,ддд,2,FALSE) -> 15/16 | G12: =VLOOKUP(E12,ддд,3,FALSE) -> 35 | H12: =VLOOKUP(E12,ддд,4,FALSE) -> 92 | I12: =VLOOKUP(E12,ддд,5,FALSE) -> 2.3492
A13: 8 | D13: 9 | E13: 5292 | F13: =VLOOKUP(E13,ддд,2,FALSE) -> 14 | G13: =VLOOKUP(E13,ддд,3,FALSE) -> 30 | H13: =VLOOKUP(E13,ддд,4,FALSE) -> 92 | I13: =VLOOKUP(E13,ддд,5,FALSE) -> 2.0136
A14: 9 | D14: 10 | E14: 2118 | F14: =VLOOKUP(E14,ддд,2,FALSE) -> 13 | G14: =VLOOKUP(E14,ддд,3,FALSE) -> 70 | H14: =VLOOKUP(E14,ддд,4,FALSE) -> 94 | I14: =VLOOKUP(E14,ддд,5,FALSE) -> 3.5238
A15: 10 | D15: 11 | E15: 8638 | F15: 15 | G15: 40 | H15: 85 | I15: 5.034
A16: 11 | D16: 12 | E16: 9641 | F16: =VLOOKUP(E16,ддд,2,FALSE) -> 14 | G16: =VLOOKUP(E16,ддд,3,FALSE) -> 40 | H16: =VLOOKUP(E16,ддд,4,FALSE) -> 85 | I16: =VLOOKUP(E16,ддд,5,FALSE) -> 5.034
A17: 12 | D17: 13 | E17: 4857 | F17: =VLOOKUP(E17,ддд,2,FALSE) -> 14 | G17: =VLOOKUP(E17,ддд,3,FALSE) -> 70 | H17: =VLOOKUP(E17,ддд,4,FALSE) -> 93 | I17: =VLOOKUP(E17,ддд,5,FALSE) -> 4.1111 | M17: Пештер
A18: 13 | D18: 14 | E18: 5672 | F18: =VLOOKUP(E18,ддд,2,FALSE) -> 15 | G18: =VLOOKUP(E18,ддд,3,FALSE) -> 30 | H18: =VLOOKUP(E18,ддд,4,FALSE) -> 92 | I18: =VLOOKUP(E18,ддд,5,FALSE) -> 2.0136 | M18: объект | N18: қосулы / өшірулі | O18: су деңгейі | P18: объект | Q18: қосулы / өшірулі | R18: су деңгейі
A19: 14 | C19: ГУ-93 ЗУ-93б | D19: 1 | E19: 7482 | F19: =VLOOKUP(E19,ддд,2,FALSE) -> 15 | G19: =VLOOKUP(E19,ддд,3,FALSE) -> 5 | H19: =VLOOKUP(E19,ддд,4,FALSE) -> 80 | I19: =VLOOKUP(E19,ддд,5,FALSE) -> 0.839
A20: 15 | D20: 2 | E20: 5719 | F20: =VLOOKUP(E20,ддд,2,FALSE) -> 14 | G20: =VLOOKUP(E20,ддд,3,FALSE) -> 50 | H20: =VLOOKUP(E20,ддд,4,FALSE) -> 90 | I20: =VLOOKUP(E20,ддд,5,FALSE) -> 4.195
A21: 16 | D21: 3 | E21: 8235 | F21: 14 | G21: =VLOOKUP(E21,ддд,3,FALSE) -> 10 | H21: =VLOOKUP(E21,ддд,4,FALSE) -> 50 | I21: =VLOOKUP(E21,ддд,5,FALSE) -> 4.195
A22: 17 | D22: 4 | E22: 2119 | F22: =VLOOKUP(E22,ддд,2,FALSE) -> 13 | G22: =VLOOKUP(E22,ддд,3,FALSE) -> 35 | H22: =VLOOKUP(E22,ддд,4,FALSE) -> 93 | I22: =VLOOKUP(E22,ддд,5,FALSE) -> 2.05555
A23: 18 | D23: 5 | E23: 7546 | F23: =VLOOKUP(E23,ддд,2,FALSE) -> 13 | G23: =VLOOKUP(E23,ддд,3,FALSE) -> 40 | H23: =VLOOKUP(E23,ддд,4,FALSE) -> 93 | I23: =VLOOKUP(E23,ддд,5,FALSE) -> 2.3492
A24: 19 | D24: 6 | E24: 8236 | F24: =VLOOKUP(E24,ддд,2,FALSE) -> 13 | G24: =VLOOKUP(E24,ддд,3,FALSE) -> 60 | H24: =VLOOKUP(E24,ддд,4,FALSE) -> 92 | I24: =VLOOKUP(E24,ддд,5,FALSE) -> 4.0272
A25: 20 | D25: 8 | E25: 4282 | F25: =VLOOKUP(E25,ддд,2,FALSE) -> 14 | G25: =VLOOKUP(E25,ддд,3,FALSE) -> 35 | H25: =VLOOKUP(E25,ддд,4,FALSE) -> 90 | I25: =VLOOKUP(E25,ддд,5,FALSE) -> 2.9365
A26: 21 | D26: 9 | E26: 8242 | F26: =VLOOKUP(E26,ддд,2,FALSE) -> 13 | G26: =VLOOKUP(E26,ддд,3,FALSE) -> 55 | H26: =VLOOKUP(E26,ддд,4,FALSE) -> 94 | I26: =VLOOKUP(E26,ддд,5,FALSE) -> 2.7687
A27: 22 | D27: 10 | E27: 4850 | F27: =VLOOKUP(E27,ддд,2,FALSE) -> 14 | G27: =VLOOKUP(E27,ддд,3,FALSE) -> 35 | H27: =VLOOKUP(E27,ддд,4,FALSE) -> 85 | I27: =VLOOKUP(E27,ддд,5,FALSE) -> 4.40475
A28: 23 | D28: 11 | E28: 8938 | F28: =VLOOKUP(E28,ддд,2,FALSE) -> 13 | G28: =VLOOKUP(E28,ддд,3,FALSE) -> 70 | H28: =VLOOKUP(E28,ддд,4,FALSE) -> 93 | I28: =VLOOKUP(E28,ддд,5,FALSE) -> 4.1111
A29: 24 | D29: 12 | E29: 8243 | F29: =VLOOKUP(E29,ддд,2,FALSE) -> 14 | G29: =VLOOKUP(E29,ддд,3,FALSE) -> 35 | H29: =VLOOKUP(E29,ддд,4,FALSE) -> 90 | I29: =VLOOKUP(E29,ддд,5,FALSE) -> 2.9365
A30: 25 | D30: 13 | E30: 9687 | F30: =VLOOKUP(E30,ддд,2,FALSE) -> 15 | G30: =VLOOKUP(E30,ддд,3,FALSE) -> 40 | H30: =VLOOKUP(E30,ддд,4,FALSE) -> 92 | I30: =VLOOKUP(E30,ддд,5,FALSE) -> 2.6848
A31: 26 | D31: 14 | E31: 1189 | M31: Сораптар
A32: 27 | C32: ГУ-93 ЗУ-93 в | D32: 1 | E32: 4615 | F32: =VLOOKUP(E32,ддд,2,FALSE) -> 13 | G32: =VLOOKUP(E32,ддд,3,FALSE) -> 25 | H32: =VLOOKUP(E32,ддд,4,FALSE) -> 75 | I32: =VLOOKUP(E32,ддд,5,FALSE) -> 5.24375 | M32: 1 | P32: 4
A33: 28 | D33: 2 | E33: 6858 | F33: =VLOOKUP(E33,ддд,2,FALSE) -> 13 | G33: =VLOOKUP(E33,ддд,3,FALSE) -> 40 | H33: =VLOOKUP(E33,ддд,4,FALSE) -> 80 | I33: =VLOOKUP(E33,ддд,5,FALSE) -> 6.712 | M33: 2 | P33: 5
A34: 29 | D34: 3 | E34: 2123 | F34: =VLOOKUP(E34,ддд,2,FALSE) -> 14 | G34: =VLOOKUP(E34,ддд,3,FALSE) -> 45 | H34: =VLOOKUP(E34,ддд,4,FALSE) -> 92 | I34: =VLOOKUP(E34,ддд,5,FALSE) -> 3.0204 | M34: 3 | P34: 6
A35: 30 | D35: 4 | E35: 2952 | F35: =VLOOKUP(E35,ддд,2,FALSE) -> 13 | G35: =VLOOKUP(E35,ддд,3,FALSE) -> 50 | H35: =VLOOKUP(E35,ддд,4,FALSE) -> 93 | I35: =VLOOKUP(E35,ддд,5,FALSE) -> 2.9365 | M35: Мұнайшылар
A36: 31 | D36: 5 | E36: 547 | F36: =VLOOKUP(E36,ддд,2,FALSE) -> 13 | G36: =VLOOKUP(E36,ддд,3,FALSE) -> 30 | H36: =VLOOKUP(E36,ддд,4,FALSE) -> 95 | I36: =VLOOKUP(E36,ддд,5,FALSE) -> 1.2585 | N36: Аты Жөні | R36: статус
A37: 32 | D37: 6 | E37: 4609 | F37: =VLOOKUP(E37,ддд,2,FALSE) -> 13 | G37: =VLOOKUP(E37,ддд,3,FALSE) -> 30 | H37: =VLOOKUP(E37,ддд,4,FALSE) -> 65 | I37: =VLOOKUP(E37,ддд,5,FALSE) -> 8.8095 | M37: 1
A38: 33 | D38: 7 | E38: 8940 | F38: =VLOOKUP(E38,ддд,2,FALSE) -> 13 | G38: =VLOOKUP(E38,ддд,3,FALSE) -> 55 | H38: =VLOOKUP(E38,ддд,4,FALSE) -> 94 | I38: =VLOOKUP(E38,ддд,5,FALSE) -> 2.7687 | M38: 2
A39: 34 | D39: 13 | E39: 1194 | F39: =VLOOKUP(E39,ддд,2,FALSE) -> 13 | G39: =VLOOKUP(E39,ддд,3,FALSE) -> 35 | H39: =VLOOKUP(E39,ддд,4,FALSE) -> 95 | I39: =VLOOKUP(E39,ддд,5,FALSE) -> 1.46825 | M39: 3
A40: 35 | D40: 14 | E40: 8529 | F40: =VLOOKUP(E40,ддд,2,FALSE) -> 16 | G40: =VLOOKUP(E40,ддд,3,FALSE) -> 30 | H40: =VLOOKUP(E40,ддд,4,FALSE) -> 50 | I40: =VLOOKUP(E40,ддд,5,FALSE) -> 12.585 | M40: 4
A41: 36 | C41: ГУ-93 ЗУ-93 г | D41: 1 | E41: 8347 | F41: =VLOOKUP(E41,ддд,2,FALSE) -> 14 | G41: =VLOOKUP(E41,ддд,3,FALSE) -> 30 | H41: =VLOOKUP(E41,ддд,4,FALSE) -> 60 | I41: =VLOOKUP(E41,ддд,5,FALSE) -> 10.068 | M41: 5
...

Sheet Карта экспорт
A1: ТҚ-93 — Excel экспорт картасы
A2: Сары бағандарды толтырыңыз: Excel-дегі лист атауы, ұяшық/диапазон және қажет болса ескерту. Журналдың баспа үлгісін өзгертпеңіз.
A4: № | B4: Қосымша бөлімі | C4: Өріс атауы | D4: Excel листі | E4: Ұяшық / диапазон | F4: Мәлімет түрі | G4: Қайталану | H4: Ескерту / үлгі
A5: 1 | B5: Журнал тақырыбы | C5: Күні | D5: 93 | E5: ='93'!I2 -> " " | F5: күн | H5: Мысалы: B2
A6: 2 | B6: Журнал тақырыбы | C6: Вахта | D6: 93 | E6: ='93'!S2 -> 0 | F6: мәтін
A7: 3 | B7: Журнал тақырыбы | C7: Шебердің аты-жөні | D7: 93 | E7: ='93'!Q2 -> 0 | F7: мәтін
A8: 4 | B8: Жалпы мәлімет | C8: Барлық скважина саны | D8: 93 | E8: ='93'!N6 -> 0 | F8: сан
A9: 5 | B9: Жалпы мәлімет | C9: Жұмыстағы скважина саны | D9: 93 | E9: ='93'!P6 -> 0 | F9: сан
A10: 6 | B10: Жалпы мәлімет | C10: Тоқтап тұрған скважина саны | D10: 93 | E10: ='93'!R6 -> 0 | F10: сан
A11: 7 | B11: Жалпы мәлімет | C11: Бас құбыр | D11: 93 | E11: ='93'!N7 -> 0 | F11: сан
A12: 8 | B12: Жалпы мәлімет | C12: Қазан | D12: 93 | E12: ='93'!P7 -> 0 | F12: сан
A13: 9 | B13: Жалпы мәлімет | C13: ГӨЗ | D13: 93 | E13: ='93'!R7 -> 0 | F13: сан
A14: 10 | B14: Буфер / затруб | C14: Скважина №____ — буфер | D14: 93 | E14: ='93'!J6 -> 0 | F14: сан не мәтін | G14: әр скважина
A15: 11 | B15: Буфер / затруб | C15: Скважина №____ — затруб | D15: 93 | E15: ='93'!K6 -> 0 | F15: сан не мәтін | G15: әр скважина
A16: 12 | B16: Буфер / затруб | C16: Скважина №____ — ескерту | D16: 93 | E16: ='93'!L6 -> 0 | F16: мәтін | G16: әр скважина | H16: Мысалы: ПРС
A17: 13 | B17: Химреагент | C17: Объект атауы | D17: 93 | E17: ='93'!M10 -> 0 | F17: мәтін | H17: 1ші қатар
A18: 14 | B18: Химреагент | C18: Объект атауы | D18: 93 | E18: ='93'!M11 -> 0 | F18: мәтін
A19: 15 | B19: Химреагент | C19: Объект атауы | D19: 93 | E19: ='93'!M12 -> 0 | F19: мәтін
A20: 16 | B20: Химреагент | C20: Объект атауы | D20: 93 | E20: ='93'!M13 -> 0 | F20: мәтін
A21: 17 | B21: Химреагент | C21: Объект атауы | D21: 93 | E21: ='93'!M14 -> 0 | F21: мәтін
A22: 18 | B22: Химреагент | C22: Объект атауы | D22: 93 | E22: ='93'!M15 -> 0 | F22: мәтін
A23: 19 | B23: Химреагент | C23: Объект атауы | D23: 93 | E23: ='93'!M16 -> 0 | F23: мәтін
A24: 20 | B24: Химреагент | C24: Объект атауы | D24: 93 | E24: ='93'!P10 -> 0 | F24: мәтін | H24: 2ші қатар
A25: 21 | B25: Химреагент | C25: Объект атауы | D25: 93 | E25: ='93'!P11 -> 0 | F25: мәтін
A26: 22 | B26: Химреагент | C26: Объект атауы | D26: 93 | E26: ='93'!P12 -> 0 | F26: мәтін
A27: 23 | B27: Химреагент | C27: Объект атауы | D27: 93 | E27: ='93'!P13 -> 0 | F27: мәтін
A28: 24 | B28: Химреагент | C28: Объект атауы | D28: 93 | E28: ='93'!P14 -> 0 | F28: мәтін
A29: 25 | B29: Химреагент | C29: Объект атауы | D29: 93 | E29: ='93'!P15 -> 0 | F29: мәтін
A30: 26 | B30: Химреагент | C30: Объект атауы | D30: 93 | E30: ='93'!P16 -> 0 | F30: мәтін
A31: 27 | B31: Химреагент | C31: Деңгейі | D31: 93 | E31: ='93'!N10 -> 0 | F31: сан не мәтін | H31: 1ші қатар
A32: 28 | B32: Химреагент | C32: Деңгейі | D32: 93 | E32: ='93'!N11 -> 0 | F32: сан не мәтін
A33: 29 | B33: Химреагент | C33: Деңгейі | D33: 93 | E33: ='93'!N12 -> 0 | F33: сан не мәтін
A34: 30 | B34: Химреагент | C34: Деңгейі | D34: 93 | E34: ='93'!N13 -> 0 | F34: сан не мәтін
A35: 31 | B35: Химреагент | C35: Деңгейі | D35: 93 | E35: ='93'!N14 -> 0 | F35: сан не мәтін
A36: 32 | B36: Химреагент | C36: Деңгейі | D36: 93 | E36: ='93'!N15 -> 0 | F36: сан не мәтін
A37: 33 | B37: Химреагент | C37: Деңгейі | D37: 93 | E37: ='93'!N16 -> 0 | F37: сан не мәтін
A38: 34 | B38: Химреагент | C38: Деңгейі | D38: 93 | E38: ='93'!Q10 -> 0 | F38: сан не мәтін | H38: 2ші қатар
A39: 35 | B39: Химреагент | C39: Деңгейі | D39: 93 | E39: ='93'!Q11 -> 0 | F39: сан не мәтін
A40: 36 | B40: Химреагент | C40: Деңгейі | D40: 93 | E40: ='93'!Q12 -> 0 | F40: сан не мәтін
A41: 37 | B41: Химреагент | C41: Деңгейі | D41: 93 | E41: ='93'!Q13 -> 0 | F41: сан не мәтін
...
